<sdf version='1.6'>
  <world name='default'>
    <light name='sun' type='directional'>
      <cast_shadows>1</cast_shadows>
      <pose frame=''>0 0 10 0 -0 0</pose>
      <diffuse>0.8 0.8 0.8 1</diffuse>
      <specular>0.1 0.1 0.1 1</specular>
      <attenuation>
        <range>1000</range>
        <constant>0.9</constant>
        <linear>0.01</linear>
        <quadratic>0.001</quadratic>
      </attenuation>
      <direction>-0.5 0.5 -1</direction>
    </light>
    <model name='ground_plane'>
      <static>1</static>
      <link name='link'>
        <collision name='collision'>
          <geometry>
            <plane>
              <normal>0 0 1</normal>
              <size>100 100</size>
            </plane>
          </geometry>
          <surface>
            <friction>
              <ode>
                <mu>100</mu>
                <mu2>50</mu2>
              </ode>
              <torsional>
                <ode/>
              </torsional>
            </friction>
            <contact>
              <ode/>
            </contact>
            <bounce/>
          </surface>
          <max_contacts>10</max_contacts>
        </collision>
        <visual name='visual'>
          <cast_shadows>0</cast_shadows>
          <geometry>
            <plane>
              <normal>0 0 1</normal>
              <size>100 100</size>
            </plane>
          </geometry>
          <material>
            <script>
              <uri>file://media/materials/scripts/gazebo.material</uri>
              <name>Gazebo/Grey</name>
            </script>
          </material>
        </visual>
        <self_collide>0</self_collide>
        <kinematic>0</kinematic>
      </link>
    </model>
    <gravity>0 0 -9.8</gravity>
    <magnetic_field>6e-06 2.3e-05 -4.2e-05</magnetic_field>
    <atmosphere type='adiabatic'/>
    <physics name='default_physics' default='0' type='ode'>
      <max_step_size>0.001</max_step_size>
      <real_time_factor>1</real_time_factor>
      <real_time_update_rate>1000</real_time_update_rate>
    </physics>
    <scene>
      <ambient>0.4 0.4 0.4 1</ambient>
      <background>0.7 0.7 0.7 1</background>
      <shadows>1</shadows>
    </scene>
    <spherical_coordinates>
      <surface_model>EARTH_WGS84</surface_model>
      <latitude_deg>0</latitude_deg>
      <longitude_deg>0</longitude_deg>
      <elevation>0</elevation>
      <heading_deg>0</heading_deg>
    </spherical_coordinates>
    <model name='coke_can'>
      <link name='link'>
        <inertial>
          <pose frame=''>0 0 0.06 0 -0 0</pose>
          <mass>0.39</mass>
          <inertia>
            <ixx>0.00055575</ixx>
            <ixy>0</ixy>
            <ixz>0</ixz>
            <iyy>0.00055575</iyy>
            <iyz>0</iyz>
            <izz>0.0001755</izz>
          </inertia>
        </inertial>
        <collision name='collision'>
          <pose frame=''>0.003937 0.004724 -0.18 0 -0 0</pose>
          <geometry>
            <mesh>
              <uri>model://coke_can/meshes/coke_can.dae</uri>
            </mesh>
          </geometry>
          <surface>
            <friction>
              <ode>
                <mu>1</mu>
                <mu2>1</mu2>
              </ode>
              <torsional>
                <ode/>
              </torsional>
            </friction>
            <contact>
              <ode>
                <kp>1e+07</kp>
                <kd>1</kd>
                <min_depth>0.001</min_depth>
                <max_vel>0.1</max_vel>
              </ode>
            </contact>
            <bounce/>
          </surface>
          <max_contacts>10</max_contacts>
        </collision>
        <visual name='visual'>
          <pose frame=''>0.003937 0.004724 -0.18 0 -0 0</pose>
          <geometry>
            <mesh>
              <uri>model://coke_can/meshes/coke_can.dae</uri>
            </mesh>
          </geometry>
        </visual>
        <self_collide>0</self_collide>
        <kinematic>0</kinematic>
      </link>
      <pose frame=''>0.438366 -5.01049 0 0 -0 0</pose>
    </model>
    <model name='cafe_table'>
      <static>1</static>
      <link name='link'>
        <collision name='surface'>
          <pose frame=''>0 0 0.755 0 -0 0</pose>
          <geometry>
            <box>
              <size>0.913 0.913 0.04</size>
            </box>
          </geometry>
          <max_contacts>10</max_contacts>
          <surface>
            <contact>
              <ode/>
            </contact>
            <bounce/>
            <friction>
              <torsional>
                <ode/>
              </torsional>
              <ode/>
            </friction>
          </surface>
        </collision>
        <collision name='column'>
          <pose frame=''>0 0 0.37 0 -0 0</pose>
          <geometry>
            <box>
              <size>0.042 0.042 0.74</size>
            </box>
          </geometry>
          <max_contacts>10</max_contacts>
          <surface>
            <contact>
              <ode/>
            </contact>
            <bounce/>
            <friction>
              <torsional>
                <ode/>
              </torsional>
              <ode/>
            </friction>
          </surface>
        </collision>
        <collision name='base'>
          <pose frame=''>0 0 0.02 0 -0 0</pose>
          <geometry>
            <box>
              <size>0.56 0.56 0.04</size>
            </box>
          </geometry>
          <max_contacts>10</max_contacts>
          <surface>
            <contact>
              <ode/>
            </contact>
            <bounce/>
            <friction>
              <torsional>
                <ode/>
              </torsional>
              <ode/>
            </friction>
          </surface>
        </collision>
        <visual name='visual'>
          <geometry>
            <mesh>
              <uri>model://cafe_table/meshes/cafe_table.dae</uri>
            </mesh>
          </geometry>
        </visual>
        <self_collide>0</self_collide>
        <kinematic>0</kinematic>
      </link>
      <pose frame=''>-1.51172 -6.31187 0 0 -0 0</pose>
    </model>
    <model name='bowl'>
      <link name='link'>
        <inertial>
          <pose frame=''>0 0 0.0175 0 -0 0</pose>
          <mass>0.1</mass>
          <inertia>
            <ixx>0.000250308</ixx>
            <ixy>0</ixy>
            <ixz>0</ixz>
            <iyy>0.000250308</iyy>
            <iyz>0</iyz>
            <izz>0.0004802</izz>
          </inertia>
        </inertial>
        <collision name='collision'>
          <pose frame=''>0 0 0.0175 0 -0 0</pose>
          <geometry>
            <cylinder>
              <radius>0.098</radius>
              <length>0.035</length>
            </cylinder>
          </geometry>
          <max_contacts>10</max_contacts>
          <surface>
            <contact>
              <ode/>
            </contact>
            <bounce/>
            <friction>
              <torsional>
                <ode/>
              </torsional>
              <ode/>
            </friction>
          </surface>
        </collision>
        <visual name='visual'>
          <geometry>
            <mesh>
              <uri>model://bowl/meshes/bowl.dae</uri>
            </mesh>
          </geometry>
        </visual>
        <self_collide>0</self_collide>
        <kinematic>0</kinematic>
      </link>
      <pose frame=''>-0.633019 -5.94693 0 0 -0 0</pose>
    </model>
    <model name='bowl_0'>
      <link name='link'>
        <inertial>
          <pose frame=''>0 0 0.0175 0 -0 0</pose>
          <mass>0.1</mass>
          <inertia>
            <ixx>0.000250308</ixx>
            <ixy>0</ixy>
            <ixz>0</ixz>
            <iyy>0.000250308</iyy>
            <iyz>0</iyz>
            <izz>0.0004802</izz>
          </inertia>
        </inertial>
        <collision name='collision'>
          <pose frame=''>0 0 0.0175 0 -0 0</pose>
          <geometry>
            <cylinder>
              <radius>0.098</radius>
              <length>0.035</length>
            </cylinder>
          </geometry>
          <max_contacts>10</max_contacts>
          <surface>
            <contact>
              <ode/>
            </contact>
            <bounce/>
            <friction>
              <torsional>
                <ode/>
              </torsional>
              <ode/>
            </friction>
          </surface>
        </collision>
        <visual name='visual'>
          <geometry>
            <mesh>
              <uri>model://bowl/meshes/bowl.dae</uri>
            </mesh>
          </geometry>
        </visual>
        <self_collide>0</self_collide>
        <kinematic>0</kinematic>
      </link>
      <pose frame=''>-0.545144 -6.51734 0 0 -0 0</pose>
    </model>
    <model name='saucepan'>
      <link name='link'>
        <inertial>
          <mass>0.1</mass>
          <inertia>
            <ixx>1</ixx>
            <ixy>0</ixy>
            <ixz>0</ixz>
            <iyy>1</iyy>
            <iyz>0</iyz>
            <izz>1</izz>
          </inertia>
        </inertial>
        <collision name='collision'>
          <geometry>
            <cylinder>
              <radius>0.127</radius>
              <length>0.058</length>
            </cylinder>
          </geometry>
          <max_contacts>10</max_contacts>
          <surface>
            <contact>
              <ode/>
            </contact>
            <bounce/>
            <friction>
              <torsional>
                <ode/>
              </torsional>
              <ode/>
            </friction>
          </surface>
        </collision>
        <visual name='visual'>
          <geometry>
            <mesh>
              <uri>model://saucepan/meshes/saucepan.dae</uri>
            </mesh>
          </geometry>
        </visual>
        <self_collide>0</self_collide>
        <kinematic>0</kinematic>
      </link>
      <pose frame=''>0.851891 -5.25798 0 0 -0 0</pose>
    </model>
    <model name='door'>
      <pose frame=''>0.011496 -1.74221 0 1.5708 -0 0</pose>
      <link name='door_frame'>
        <inertial>
          <pose frame=''>0.525 1 0.05 0 -0 0</pose>
          <mass>30</mass>
          <inertia>
            <ixx>1</ixx>
            <ixy>0</ixy>
            <ixz>0</ixz>
            <iyy>1</iyy>
            <iyz>0</iyz>
            <izz>1</izz>
          </inertia>
        </inertial>
        <visual name='visual_frame'>
          <pose frame=''>0 0 0 0 -0 0</pose>
          <geometry>
            <mesh>
              <uri>model://door/meshes/frame.stl</uri>
              <scale>0.1 0.1 0.1</scale>
            </mesh>
          </geometry>
        </visual>
        <collision name='collision_frame'>
          <pose frame=''>0 0 0 0 -0 0</pose>
          <geometry>
            <mesh>
              <uri>model://door/meshes/frame.stl</uri>
              <scale>0.1 0.1 0.1</scale>
            </mesh>
          </geometry>
          <max_contacts>10</max_contacts>
          <surface>
            <contact>
              <ode/>
            </contact>
            <bounce/>
            <friction>
              <torsional>
                <ode/>
              </torsional>
              <ode/>
            </friction>
          </surface>
        </collision>
        <self_collide>0</self_collide>
        <kinematic>0</kinematic>
      </link>
      <link name='door_body'>
        <inertial>
          <pose frame=''>0.525 1 0.05 0 -0 0</pose>
          <mass>1</mass>
          <inertia>
            <ixx>0.083</ixx>
            <ixy>0</ixy>
            <ixz>0</ixz>
            <iyy>0.083</iyy>
            <iyz>0</iyz>
            <izz>0.083</izz>
          </inertia>
        </inertial>
        <collision name='collision_door'>
          <pose frame=''>0.525 0.995 0.05 0 -0 0</pose>
          <geometry>
            <box>
              <size>0.9 1.99 0.03</size>
            </box>
          </geometry>
          <max_contacts>10</max_contacts>
          <surface>
            <contact>
              <ode/>
            </contact>
            <bounce/>
            <friction>
              <torsional>
                <ode/>
              </torsional>
              <ode/>
            </friction>
          </surface>
        </collision>
        <visual name='visual_door'>
          <pose frame=''>0.525 0.995 0.05 0 -0 0</pose>
          <geometry>
            <box>
              <size>0.9 1.99 0.03</size>
            </box>
          </geometry>
        </visual>
        <self_collide>0</self_collide>
        <kinematic>0</kinematic>
      </link>
      <link name='door_handle'>
        <inertial>
          <pose frame=''>0.8 1 0.15 -3.14159 -0 0</pose>
          <mass>1</mass>
          <inertia>
            <ixx>1</ixx>
            <ixy>0</ixy>
            <ixz>0</ixz>
            <iyy>1</iyy>
            <iyz>0</iyz>
            <izz>1</izz>
          </inertia>
        </inertial>
        <visual name='visual_handle'>
          <pose frame=''>0.9 1 0.15 -3.14159 0.001593 -1.57159</pose>
          <geometry>
            <mesh>
              <uri>model://door/meshes/handle.stl</uri>
              <scale>0.002 0.002 0.002</scale>
            </mesh>
          </geometry>
        </visual>
        <collision name='collision_handle'>
          <pose frame=''>0.9 1 0.15 -3.14159 0.001593 -1.57159</pose>
          <geometry>
            <mesh>
              <uri>model://door/meshes/handle.stl</uri>
              <scale>0.002 0.002 0.002</scale>
            </mesh>
          </geometry>
          <max_contacts>10</max_contacts>
          <surface>
            <contact>
              <ode/>
            </contact>
            <bounce/>
            <friction>
              <torsional>
                <ode/>
              </torsional>
              <ode/>
            </friction>
          </surface>
        </collision>
        <self_collide>0</self_collide>
        <kinematic>0</kinematic>
      </link>
      <joint name='door_body_handle' type='revolute'>
        <parent>door_body</parent>
        <child>door_handle</child>
        <pose frame=''>0.075 0 0.065 0 -0 0</pose>
        <axis>
          <xyz>0 1 0</xyz>
          <dynamics>
            <damping>0.1</damping>
            <friction>0.1</friction>
            <spring_reference>0</spring_reference>
            <spring_stiffness>0</spring_stiffness>
          </dynamics>
          <limit>
            <lower>0</lower>
            <upper>0</upper>
          </limit>
          <use_parent_model_frame>1</use_parent_model_frame>
        </axis>
      </joint>
      <joint name='door_hinge' type='revolute'>
        <parent>door_frame</parent>
        <child>door_body</child>
        <pose frame=''>0.075 0 0.065 0 -0 0</pose>
        <axis>
          <xyz>0 1 0</xyz>
          <dynamics>
            <damping>0.1</damping>
            <friction>0.1</friction>
            <spring_reference>0</spring_reference>
            <spring_stiffness>0</spring_stiffness>
          </dynamics>
          <limit>
            <lower>-1.57</lower>
            <upper>1.57</upper>
            <velocity>1</velocity>
          </limit>
          <use_parent_model_frame>1</use_parent_model_frame>
        </axis>
      </joint>
      <joint name='world_joint' type='revolute'>
        <child>door_frame</child>
        <parent>world</parent>
        <axis>
          <limit>
            <lower>0</lower>
            <upper>0</upper>
          </limit>
          <xyz>0 1 0</xyz>
          <dynamics>
            <damping>1</damping>
            <spring_reference>0</spring_reference>
            <spring_stiffness>0</spring_stiffness>
          </dynamics>
          <use_parent_model_frame>1</use_parent_model_frame>
          <use_parent_model_frame>1</use_parent_model_frame>
        </axis>
        <physics>
          <ode>
            <cfm_damping>1</cfm_damping>
            <limit>
              <cfm>0</cfm>
              <erp>0.2</erp>
            </limit>
          </ode>
        </physics>
      </joint>
    </model>
    <model name='coke_can_0'>
      <link name='link'>
        <inertial>
          <pose frame=''>0 0 0.06 0 -0 0</pose>
          <mass>0.39</mass>
          <inertia>
            <ixx>0.00055575</ixx>
            <ixy>0</ixy>
            <ixz>0</ixz>
            <iyy>0.00055575</iyy>
            <iyz>0</iyz>
            <izz>0.0001755</izz>
          </inertia>
        </inertial>
        <collision name='collision'>
          <pose frame=''>0.003937 0.004724 -0.18 0 -0 0</pose>
          <geometry>
            <mesh>
              <uri>model://coke_can/meshes/coke_can.dae</uri>
            </mesh>
          </geometry>
          <surface>
            <friction>
              <ode>
                <mu>1</mu>
                <mu2>1</mu2>
              </ode>
              <torsional>
                <ode/>
              </torsional>
            </friction>
            <contact>
              <ode>
                <kp>1e+07</kp>
                <kd>1</kd>
                <min_depth>0.001</min_depth>
                <max_vel>0.1</max_vel>
              </ode>
            </contact>
            <bounce/>
          </surface>
          <max_contacts>10</max_contacts>
        </collision>
        <visual name='visual'>
          <pose frame=''>0.003937 0.004724 -0.18 0 -0 0</pose>
          <geometry>
            <mesh>
              <uri>model://coke_can/meshes/coke_can.dae</uri>
            </mesh>
          </geometry>
        </visual>
        <self_collide>0</self_collide>
        <kinematic>0</kinematic>
      </link>
      <pose frame=''>0.586448 -4.87865 0 0 -0 0</pose>
    </model>
    <model name='beer'>
      <link name='link'>
        <pose frame=''>0 0 0.115 0 -0 0</pose>
        <inertial>
          <mass>0.39</mass>
          <inertia>
            <ixx>0.00058</ixx>
            <ixy>0</ixy>
            <ixz>0</ixz>
            <iyy>0.00058</iyy>
            <iyz>0</iyz>
            <izz>0.00019</izz>
          </inertia>
        </inertial>
        <collision name='collision'>
          <geometry>
            <cylinder>
              <radius>0.055</radius>
              <length>0.23</length>
            </cylinder>
          </geometry>
          <max_contacts>10</max_contacts>
          <surface>
            <contact>
              <ode/>
            </contact>
            <bounce/>
            <friction>
              <torsional>
                <ode/>
              </torsional>
              <ode/>
            </friction>
          </surface>
        </collision>
        <visual name='visual'>
          <geometry>
            <cylinder>
              <radius>0.055</radius>
              <length>0.23</length>
            </cylinder>
          </geometry>
          <material>
            <script>
              <uri>model://beer/materials/scripts</uri>
              <uri>model://beer/materials/textures</uri>
              <name>Beer/Diffuse</name>
            </script>
          </material>
        </visual>
        <self_collide>0</self_collide>
        <kinematic>0</kinematic>
      </link>
      <pose frame=''>1.88651 -5.18992 0 0 -0 0</pose>
    </model>
    <model name='cessna_c172'>
      <pose frame=''>-4.03831 -5.63364 0.495 0 -0 0</pose>
      <link name='body'>
        <inertial>
          <mass>680.389</mass>
          <inertia>
            <ixx>1285.32</ixx>
            <ixy>0</ixy>
            <iyy>1824.93</iyy>
            <ixz>0</ixz>
            <iyz>0</iyz>
            <izz>2666.89</izz>
          </inertia>
          <pose frame=''>-0.0414 0 0.9271 0 -0 0</pose>
        </inertial>
        <collision name='collision'>
          <geometry>
            <mesh>
              <uri>model://cessna/meshes/body.dae</uri>
            </mesh>
          </geometry>
          <max_contacts>10</max_contacts>
          <surface>
            <contact>
              <ode/>
            </contact>
            <bounce/>
            <friction>
              <torsional>
                <ode/>
              </torsional>
              <ode/>
            </friction>
          </surface>
        </collision>
        <visual name='visual'>
          <geometry>
            <mesh>
              <uri>model://cessna/meshes/body.dae</uri>
            </mesh>
          </geometry>
        </visual>
        <self_collide>0</self_collide>
        <kinematic>0</kinematic>
      </link>
      <link name='left_aileron'>
        <inertial>
          <mass>2</mass>
          <inertia>
            <ixx>0.8434</ixx>
            <ixy>0</ixy>
            <iyy>0.0119</iyy>
            <ixz>0</ixz>
            <iyz>0</iyz>
            <izz>0.855</izz>
          </inertia>
          <pose frame=''>-1.65 3.7 1.5 0.05 -0 -0.12</pose>
        </inertial>
        <collision name='collision'>
          <geometry>
            <mesh>
              <uri>model://cessna/meshes/left_aileron.dae</uri>
            </mesh>
          </geometry>
          <max_contacts>10</max_contacts>
          <surface>
            <contact>
              <ode/>
            </contact>
            <bounce/>
            <friction>
              <torsional>
                <ode/>
              </torsional>
              <ode/>
            </friction>
          </surface>
        </collision>
        <visual name='visual'>
          <geometry>
            <mesh>
              <uri>model://cessna/meshes/left_aileron.dae</uri>
            </mesh>
          </geometry>
        </visual>
        <self_collide>0</self_collide>
        <kinematic>0</kinematic>
      </link>
      <link name='left_flap'>
        <inertial>
          <mass>2</mass>
          <inertia>
            <ixx>0.6747</ixx>
            <ixy>0</ixy>
            <iyy>0.0242</iyy>
            <ixz>0</ixz>
            <iyz>0</iyz>
            <izz>0.6962</izz>
          </inertia>
          <pose frame=''>-1.8 1.55 1.43 0.02 -0 0</pose>
        </inertial>
        <collision name='collision'>
          <geometry>
            <mesh>
              <uri>model://cessna/meshes/left_flap.dae</uri>
            </mesh>
          </geometry>
          <max_contacts>10</max_contacts>
          <surface>
            <contact>
              <ode/>
            </contact>
            <bounce/>
            <friction>
              <torsional>
                <ode/>
              </torsional>
              <ode/>
            </friction>
          </surface>
        </collision>
        <visual name='visual'>
          <geometry>
            <mesh>
              <uri>model://cessna/meshes/left_flap.dae</uri>
            </mesh>
          </geometry>
        </visual>
        <self_collide>0</self_collide>
        <kinematic>0</kinematic>
      </link>
      <link name='right_aileron'>
        <inertial>
          <mass>2</mass>
          <inertia>
            <ixx>0.8434</ixx>
            <ixy>0</ixy>
            <iyy>0.0119</iyy>
            <ixz>0</ixz>
            <iyz>0</iyz>
            <izz>0.855</izz>
          </inertia>
          <pose frame=''>-1.65 -3.7 1.5 -0.05 -0 0.12</pose>
        </inertial>
        <collision name='collision'>
          <geometry>
            <mesh>
              <uri>model://cessna/meshes/right_aileron.dae</uri>
            </mesh>
          </geometry>
          <max_contacts>10</max_contacts>
          <surface>
            <contact>
              <ode/>
            </contact>
            <bounce/>
            <friction>
              <torsional>
                <ode/>
              </torsional>
              <ode/>
            </friction>
          </surface>
        </collision>
        <visual name='visual'>
          <geometry>
            <mesh>
              <uri>model://cessna/meshes/right_aileron.dae</uri>
            </mesh>
          </geometry>
        </visual>
        <self_collide>0</self_collide>
        <kinematic>0</kinematic>
      </link>
      <link name='right_flap'>
        <inertial>
          <mass>2</mass>
          <inertia>
            <ixx>0.6747</ixx>
            <ixy>0</ixy>
            <iyy>0.0242</iyy>
            <ixz>0</ixz>
            <iyz>0</iyz>
            <izz>0.6962</izz>
          </inertia>
          <pose frame=''>-1.8 -1.55 1.43 -0.02 0 0</pose>
        </inertial>
        <collision name='collision'>
          <geometry>
            <mesh>
              <uri>model://cessna/meshes/right_flap.dae</uri>
            </mesh>
          </geometry>
          <max_contacts>10</max_contacts>
          <surface>
            <contact>
              <ode/>
            </contact>
            <bounce/>
            <friction>
              <torsional>
                <ode/>
              </torsional>
              <ode/>
            </friction>
          </surface>
        </collision>
        <visual name='visual'>
          <geometry>
            <mesh>
              <uri>model://cessna/meshes/right_flap.dae</uri>
            </mesh>
          </geometry>
        </visual>
        <self_collide>0</self_collide>
        <kinematic>0</kinematic>
      </link>
      <link name='elevators'>
        <inertial>
          <mass>2</mass>
          <inertia>
            <ixx>1.5008</ixx>
            <ixy>0</ixy>
            <iyy>0.0274</iyy>
            <ixz>0</ixz>
            <iyz>0</iyz>
            <izz>1.5266</izz>
          </inertia>
          <pose frame=''>-5.75 0 0.57 0 -0 0</pose>
        </inertial>
        <collision name='collision'>
          <geometry>
            <mesh>
              <uri>model://cessna/meshes/elevators.dae</uri>
            </mesh>
          </geometry>
          <max_contacts>10</max_contacts>
          <surface>
            <contact>
              <ode/>
            </contact>
            <bounce/>
            <friction>
              <torsional>
                <ode/>
              </torsional>
              <ode/>
            </friction>
          </surface>
        </collision>
        <visual name='visual'>
          <geometry>
            <mesh>
              <uri>model://cessna/meshes/elevators.dae</uri>
            </mesh>
          </geometry>
        </visual>
        <self_collide>0</self_collide>
        <kinematic>0</kinematic>
      </link>
      <link name='rudder'>
        <inertial>
          <mass>2</mass>
          <inertia>
            <ixx>0.4708</ixx>
            <ixy>0</ixy>
            <iyy>0.5208</iyy>
            <ixz>0</ixz>
            <iyz>0</iyz>
            <izz>0.0508</izz>
          </inertia>
          <pose frame=''>-6.1 0 1.3 0 -0.35 0</pose>
        </inertial>
        <collision name='collision'>
          <geometry>
            <mesh>
              <uri>model://cessna/meshes/rudder.dae</uri>
            </mesh>
          </geometry>
          <max_contacts>10</max_contacts>
          <surface>
            <contact>
              <ode/>
            </contact>
            <bounce/>
            <friction>
              <torsional>
                <ode/>
              </torsional>
              <ode/>
            </friction>
          </surface>
        </collision>
        <visual name='visual'>
          <geometry>
            <mesh>
              <uri>model://cessna/meshes/rudder.dae</uri>
            </mesh>
          </geometry>
        </visual>
        <self_collide>0</self_collide>
        <kinematic>0</kinematic>
      </link>
      <link name='propeller'>
        <pose frame=''>1.79 0 0.855 0 -0 0</pose>
        <inertial>
          <mass>18.37</mass>
          <inertia>
            <ixx>7.5067</ixx>
            <ixy>0</ixy>
            <iyy>7.515</iyy>
            <ixz>0</ixz>
            <iyz>0</iyz>
            <izz>0.068275</izz>
          </inertia>
          <pose frame=''>-0.35 0 0 0 -0 0</pose>
        </inertial>
        <collision name='collision'>
          <geometry>
            <mesh>
              <uri>model://cessna/meshes/cessna_prop.dae</uri>
            </mesh>
          </geometry>
          <max_contacts>10</max_contacts>
          <surface>
            <contact>
              <ode/>
            </contact>
            <bounce/>
            <friction>
              <torsional>
                <ode/>
              </torsional>
              <ode/>
            </friction>
          </surface>
        </collision>
        <visual name='visual'>
          <geometry>
            <mesh>
              <uri>model://cessna/meshes/cessna_prop.dae</uri>
            </mesh>
          </geometry>
        </visual>
        <self_collide>0</self_collide>
        <kinematic>0</kinematic>
      </link>
      <link name='front_wheel'>
        <inertial>
          <mass>2</mass>
          <inertia>
            <ixx>0.01786</ixx>
            <ixy>0</ixy>
            <iyy>0.01786</iyy>
            <ixz>0</ixz>
            <iyz>0</iyz>
            <izz>0.0324</izz>
          </inertia>
          <pose frame=''>0.712 0 -0.313 1.57079 -0 0</pose>
        </inertial>
        <collision name='collision'>
          <pose frame=''>0.712 0 -0.313 1.57079 -0 0</pose>
          <geometry>
            <cylinder>
              <radius>0.18</radius>
              <length>0.1</length>
            </cylinder>
          </geometry>
          <surface>
            <friction>
              <ode>
                <mu>0.3</mu>
                <mu2>0.3</mu2>
              </ode>
              <torsional>
                <ode/>
              </torsional>
            </friction>
            <contact>
              <ode>
                <max_vel>0.1</max_vel>
                <min_depth>0.001</min_depth>
              </ode>
            </contact>
            <bounce/>
          </surface>
          <max_contacts>10</max_contacts>
        </collision>
        <visual name='visual'>
          <geometry>
            <mesh>
              <uri>model://cessna/meshes/cessna_front_wheel.dae</uri>
            </mesh>
          </geometry>
        </visual>
        <self_collide>0</self_collide>
        <kinematic>0</kinematic>
      </link>
      <link name='rear_left_wheel'>
        <inertial>
          <mass>2</mass>
          <inertia>
            <ixx>0.035516</ixx>
            <ixy>0</ixy>
            <iyy>0.035516</iyy>
            <ixz>0</ixz>
            <iyz>0</iyz>
            <izz>0.0625</izz>
          </inertia>
          <pose frame=''>-1 1.27 -0.25 1.57079 -0 0</pose>
        </inertial>
        <collision name='collision'>
          <pose frame=''>-1 1.27 -0.25 1.57079 -0 0</pose>
          <geometry>
            <cylinder>
              <radius>0.25</radius>
              <length>0.16</length>
            </cylinder>
          </geometry>
          <surface>
            <friction>
              <ode>
                <mu>0.3</mu>
                <mu2>0.3</mu2>
              </ode>
              <torsional>
                <ode/>
              </torsional>
            </friction>
            <contact>
              <ode>
                <max_vel>0.1</max_vel>
                <min_depth>0.001</min_depth>
              </ode>
            </contact>
            <bounce/>
          </surface>
          <max_contacts>10</max_contacts>
        </collision>
        <visual name='visual'>
          <geometry>
            <mesh>
              <uri>model://cessna/meshes/cessna_rear_left_wheel.dae</uri>
            </mesh>
          </geometry>
        </visual>
        <self_collide>0</self_collide>
        <kinematic>0</kinematic>
      </link>
      <link name='rear_right_wheel'>
        <inertial>
          <mass>2</mass>
          <inertia>
            <ixx>0.035516</ixx>
            <ixy>0</ixy>
            <iyy>0.035516</iyy>
            <ixz>0</ixz>
            <iyz>0</iyz>
            <izz>0.0625</izz>
          </inertia>
          <pose frame=''>-1 -1.27 -0.25 1.57079 -0 0</pose>
        </inertial>
        <collision name='collision'>
          <pose frame=''>-1 -1.27 -0.25 1.57079 -0 0</pose>
          <geometry>
            <cylinder>
              <radius>0.25</radius>
              <length>0.16</length>
            </cylinder>
          </geometry>
          <surface>
            <friction>
              <ode>
                <mu>0.3</mu>
                <mu2>0.3</mu2>
              </ode>
              <torsional>
                <ode/>
              </torsional>
            </friction>
            <contact>
              <ode>
                <max_vel>0.1</max_vel>
                <min_depth>0.001</min_depth>
              </ode>
            </contact>
            <bounce/>
          </surface>
          <max_contacts>10</max_contacts>
        </collision>
        <visual name='visual'>
          <geometry>
            <mesh>
              <uri>model://cessna/meshes/cessna_rear_right_wheel.dae</uri>
            </mesh>
          </geometry>
        </visual>
        <self_collide>0</self_collide>
        <kinematic>0</kinematic>
      </link>
      <joint name='left_flap_joint' type='revolute'>
        <parent>body</parent>
        <child>left_flap</child>
        <pose frame=''>-1.6 1.55 1.43 0.02 -0 0</pose>
        <axis>
          <xyz>0 1 0</xyz>
          <limit>
            <lower>-0.53</lower>
            <upper>0.53</upper>
            <effort>-1</effort>
            <velocity>-1</velocity>
          </limit>
          <dynamics>
            <damping>1</damping>
            <spring_reference>0</spring_reference>
            <spring_stiffness>0</spring_stiffness>
          </dynamics>
          <use_parent_model_frame>0</use_parent_model_frame>
        </axis>
        <physics>
          <ode>
            <implicit_spring_damper>1</implicit_spring_damper>
            <limit>
              <cfm>0</cfm>
              <erp>0.2</erp>
            </limit>
          </ode>
        </physics>
      </joint>
      <joint name='left_aileron_joint' type='revolute'>
        <parent>body</parent>
        <child>left_aileron</child>
        <pose frame=''>-1.45 3.7 1.5 0.05 -0 -0.12</pose>
        <axis>
          <xyz>0 1 0</xyz>
          <limit>
            <lower>-0.53</lower>
            <upper>0.53</upper>
            <effort>-1</effort>
            <velocity>-1</velocity>
          </limit>
          <dynamics>
            <damping>1</damping>
            <spring_reference>0</spring_reference>
            <spring_stiffness>0</spring_stiffness>
          </dynamics>
          <use_parent_model_frame>0</use_parent_model_frame>
        </axis>
        <physics>
          <ode>
            <implicit_spring_damper>1</implicit_spring_damper>
            <limit>
              <cfm>0</cfm>
              <erp>0.2</erp>
            </limit>
          </ode>
        </physics>
      </joint>
      <joint name='right_flap_joint' type='revolute'>
        <parent>body</parent>
        <child>right_flap</child>
        <pose frame=''>-1.6 -1.55 1.43 -0.02 0 0</pose>
        <axis>
          <xyz>0 1 0</xyz>
          <limit>
            <lower>-0.53</lower>
            <upper>0.53</upper>
            <effort>-1</effort>
            <velocity>-1</velocity>
          </limit>
          <dynamics>
            <damping>1</damping>
            <spring_reference>0</spring_reference>
            <spring_stiffness>0</spring_stiffness>
          </dynamics>
          <use_parent_model_frame>0</use_parent_model_frame>
        </axis>
        <physics>
          <ode>
            <implicit_spring_damper>1</implicit_spring_damper>
            <limit>
              <cfm>0</cfm>
              <erp>0.2</erp>
            </limit>
          </ode>
        </physics>
      </joint>
      <joint name='right_aileron_joint' type='revolute'>
        <parent>body</parent>
        <child>right_aileron</child>
        <pose frame=''>-1.45 -3.7 1.5 -0.05 -0 0.12</pose>
        <axis>
          <xyz>0 1 0</xyz>
          <limit>
            <lower>-0.53</lower>
            <upper>0.53</upper>
            <effort>-1</effort>
            <velocity>-1</velocity>
          </limit>
          <dynamics>
            <damping>1</damping>
            <spring_reference>0</spring_reference>
            <spring_stiffness>0</spring_stiffness>
          </dynamics>
          <use_parent_model_frame>0</use_parent_model_frame>
        </axis>
        <physics>
          <ode>
            <implicit_spring_damper>1</implicit_spring_damper>
            <limit>
              <cfm>0</cfm>
              <erp>0.2</erp>
            </limit>
          </ode>
        </physics>
      </joint>
      <joint name='elevators_joint' type='revolute'>
        <parent>body</parent>
        <child>elevators</child>
        <pose frame=''>-5.55 0 0.57 0 -0 0</pose>
        <axis>
          <xyz>0 1 0</xyz>
          <limit>
            <lower>-0.53</lower>
            <upper>0.53</upper>
            <effort>-1</effort>
            <velocity>-1</velocity>
          </limit>
          <dynamics>
            <damping>1</damping>
            <spring_reference>0</spring_reference>
            <spring_stiffness>0</spring_stiffness>
          </dynamics>
          <use_parent_model_frame>0</use_parent_model_frame>
        </axis>
        <physics>
          <ode>
            <implicit_spring_damper>1</implicit_spring_damper>
            <limit>
              <cfm>0</cfm>
              <erp>0.2</erp>
            </limit>
          </ode>
        </physics>
      </joint>
      <joint name='rudder_joint' type='revolute'>
        <parent>body</parent>
        <child>rudder</child>
        <pose frame=''>-5.9 0 1.3 0 -0.35 0</pose>
        <axis>
          <xyz>0 0 1</xyz>
          <limit>
            <lower>-0.53</lower>
            <upper>0.53</upper>
            <effort>-1</effort>
            <velocity>-1</velocity>
          </limit>
          <dynamics>
            <damping>1</damping>
            <spring_reference>0</spring_reference>
            <spring_stiffness>0</spring_stiffness>
          </dynamics>
          <use_parent_model_frame>0</use_parent_model_frame>
        </axis>
        <physics>
          <ode>
            <implicit_spring_damper>1</implicit_spring_damper>
            <limit>
              <cfm>0</cfm>
              <erp>0.2</erp>
            </limit>
          </ode>
        </physics>
      </joint>
      <joint name='propeller_joint' type='revolute'>
        <parent>body</parent>
        <child>propeller</child>
        <axis>
          <xyz>1 0 0</xyz>
          <limit>
            <lower>-1e+12</lower>
            <upper>1e+12</upper>
            <effort>-1</effort>
            <velocity>-1</velocity>
          </limit>
          <dynamics>
            <damping>0.001</damping>
            <spring_reference>0</spring_reference>
            <spring_stiffness>0</spring_stiffness>
          </dynamics>
          <use_parent_model_frame>0</use_parent_model_frame>
        </axis>
        <physics>
          <ode>
            <implicit_spring_damper>1</implicit_spring_damper>
            <limit>
              <cfm>0</cfm>
              <erp>0.2</erp>
            </limit>
          </ode>
        </physics>
      </joint>
      <joint name='front_wheel_joint' type='revolute'>
        <parent>body</parent>
        <child>front_wheel</child>
        <pose frame=''>0.712 0 -0.313 0 -0 0</pose>
        <axis>
          <xyz>0 1 0</xyz>
          <limit>
            <lower>-1e+12</lower>
            <upper>1e+12</upper>
            <effort>-1</effort>
            <velocity>-1</velocity>
          </limit>
          <dynamics>
            <damping>0.01</damping>
            <spring_reference>0</spring_reference>
            <spring_stiffness>0</spring_stiffness>
          </dynamics>
          <use_parent_model_frame>0</use_parent_model_frame>
        </axis>
        <physics>
          <ode>
            <implicit_spring_damper>1</implicit_spring_damper>
            <limit>
              <cfm>0</cfm>
              <erp>0.2</erp>
            </limit>
          </ode>
        </physics>
      </joint>
      <joint name='rear_left_wheel_joint' type='revolute'>
        <parent>body</parent>
        <child>rear_left_wheel</child>
        <pose frame=''>-1 -1.27 -0.25 0 -0 0</pose>
        <axis>
          <xyz>0 1 0</xyz>
          <limit>
            <lower>-1e+12</lower>
            <upper>1e+12</upper>
            <effort>-1</effort>
            <velocity>-1</velocity>
          </limit>
          <dynamics>
            <damping>0.01</damping>
            <spring_reference>0</spring_reference>
            <spring_stiffness>0</spring_stiffness>
          </dynamics>
          <use_parent_model_frame>0</use_parent_model_frame>
        </axis>
        <physics>
          <ode>
            <implicit_spring_damper>1</implicit_spring_damper>
            <limit>
              <cfm>0</cfm>
              <erp>0.2</erp>
            </limit>
          </ode>
        </physics>
      </joint>
      <joint name='rear_right_wheel_joint' type='revolute'>
        <parent>body</parent>
        <child>rear_right_wheel</child>
        <pose frame=''>-1 1.27 -0.25 0 -0 0</pose>
        <axis>
          <xyz>0 1 0</xyz>
          <limit>
            <lower>-1e+12</lower>
            <upper>1e+12</upper>
            <effort>-1</effort>
            <velocity>-1</velocity>
          </limit>
          <dynamics>
            <damping>0.01</damping>
            <spring_reference>0</spring_reference>
            <spring_stiffness>0</spring_stiffness>
          </dynamics>
          <use_parent_model_frame>0</use_parent_model_frame>
        </axis>
        <physics>
          <ode>
            <implicit_spring_damper>1</implicit_spring_damper>
            <limit>
              <cfm>0</cfm>
              <erp>0.2</erp>
            </limit>
          </ode>
        </physics>
      </joint>
    </model>
    <state world_name='default'>
      <sim_time>882 893000000</sim_time>
      <real_time>998 325997683</real_time>
      <wall_time>1589273313 616627684</wall_time>
      <iterations>717363</iterations>
      <model name='Mailbox'>
        <pose frame=''>2.6856 -0.115523 -1e-05 -6e-06 1e-06 0</pose>
        <scale>1 1 1</scale>
        <link name='link'>
          <pose frame=''>2.6856 -0.115523 -1e-05 -6e-06 1e-06 0</pose>
          <velocity>0 0 0 0 -0 0</velocity>
          <acceleration>0 0 -9.8 0 -0 0</acceleration>
          <wrench>0 0 -9.8 0 -0 0</wrench>
        </link>
      </model>
      <model name='beer'>
        <pose frame=''>1.09723 -7.72779 1.01521 0.000473 -0.004039 -0.050806</pose>
        <scale>1 1 1</scale>
        <link name='link'>
          <pose frame=''>1.09677 -7.72782 1.13021 0.000473 -0.004039 -0.050806</pose>
          <velocity>0 0 0 0 -0 0</velocity>
          <acceleration>0 0 -9.8 0 -0 0</acceleration>
          <wrench>0 0 -3.822 0 -0 0</wrench>
        </link>
      </model>
      <model name='bowl'>
        <pose frame=''>-1.33708 -5.93387 0.774997 -1.5e-05 -1.1e-05 -9.9e-05</pose>
        <scale>1 1 1</scale>
        <link name='link'>
          <pose frame=''>-1.33708 -5.93387 0.774997 -1.5e-05 -1.1e-05 -9.9e-05</pose>
          <velocity>0 0 0 0 -0 0</velocity>
          <acceleration>0 0 -9.8 0 -0 0</acceleration>
          <wrench>0 0 -0.98 0 -0 0</wrench>
        </link>
      </model>
      <model name='bowl_0'>
        <pose frame=''>-1.44247 -6.52471 0.774999 3.4e-05 1.5e-05 -0.011571</pose>
        <scale>1 1 1</scale>
        <link name='link'>
          <pose frame=''>-1.44247 -6.52471 0.774999 3.4e-05 1.5e-05 -0.011571</pose>
          <velocity>0 0 0 0 -0 0</velocity>
          <acceleration>0 0 -9.8 0 -0 0</acceleration>
          <wrench>0 0 -0.98 0 -0 0</wrench>
        </link>
      </model>
      <model name='cafe_table'>
        <pose frame=''>-1.51172 -6.31187 0 0 -0 0</pose>
        <scale>1 1 1</scale>
        <link name='link'>
          <pose frame=''>-1.51172 -6.31187 0 0 -0 0</pose>
          <velocity>0 0 0 0 -0 0</velocity>
          <acceleration>0 0 0 0 -0 0</acceleration>
          <wrench>0 0 0 0 -0 0</wrench>
        </link>
      </model>
      <model name='cessna_c172'>
        <pose frame=''>-5.30807 -5.6888 0.492412 0.000368 -0.000653 -0.050781</pose>
        <scale>1 1 1</scale>
        <link name='body'>
          <pose frame=''>-5.30807 -5.6888 0.492412 0.000368 -0.000653 -0.050781</pose>
          <velocity>-0.006759 0.00114 0.005634 0.001991 0.004089 0.000672</velocity>
          <acceleration>0.008359 0.374605 0.81063 -0.067769 -0.140525 0.039288</acceleration>
          <wrench>5.6875 254.877 551.544 0 -0 0</wrench>
        </link>
        <link name='elevators'>
          <pose frame=''>-5.78268 -5.66575 3.37603 0.000427 -0.530658 -0.050997</pose>
          <velocity>0.008271 -0.005084 0.000484 0.002063 0.005493 0.000673</velocity>
          <acceleration>0.097582 0.116716 -0.075521 -0.124261 -0.727014 0.038495</acceleration>
          <wrench>0.195165 0.233431 -0.151042 0 -0 0</wrench>
        </link>
        <link name='front_wheel'>
          <pose frame=''>-5.19288 -5.6946 0.678675 0.000169 0.281825 -0.050737</pose>
          <velocity>-0.030023 0.012963 -0.022486 -0.020147 -0.04417 0.000639</velocity>
          <acceleration>0.168499 -0.205023 0.199434 1.17576 0.931219 0.071155</acceleration>
          <wrench>0.336999 -0.410046 0.398868 0 -0 0</wrench>
        </link>
        <link name='left_aileron'>
          <pose frame=''>-4.91378 -5.81479 1.62443 -0.061636 -0.526667 -0.061407</pose>
          <velocity>-0.002386 -0.000545 -0.001054 0.002346 0.006145 0.000777</velocity>
          <acceleration>-0.1554 0.349042 0.272401 -0.243358 -0.943742 -0.00262</acceleration>
          <wrench>-0.3108 0.698084 0.544803 0 -0 0</wrench>
        </link>
        <link name='left_flap'>
          <pose frame=''>-4.8228 -5.73388 1.49328 0.003615 -0.530537 -0.062719</pose>
          <velocity>-0.003308 -0.00042 -3.2e-05 0.002078 0.005799 0.000707</velocity>
          <acceleration>-0.069809 0.337388 0.392861 -0.125873 -0.696664 0.026905</acceleration>
          <wrench>-0.139618 0.674777 0.785722 0 -0 0</wrench>
        </link>
        <link name='propeller'>
          <pose frame=''>-3.52096 -5.77995 1.34858 0.358966 -0.000649 -0.050783</pose>
          <velocity>-0.003197 0.000599 -0.001901 0.000792 0.004242 0.000628</velocity>
          <acceleration>0.021011 0.441683 1.03049 2.99374 -0.322966 -2.41829</acceleration>
          <wrench>0.385964 8.11371 18.93 0 -0 0</wrench>
        </link>
        <link name='rear_left_wheel'>
          <pose frame=''>-5.95504 -5.65619 -0.718793 -0.003802 1.46725 -0.05457</pose>
          <velocity>0.030612 -0.002902 0.02356 -0.003977 -0.041378 0.00065</velocity>
          <acceleration>-0.050745 0.20199 -0.059699 -0.773479 -0.201224 0.047308</acceleration>
          <wrench>-0.10149 0.40398 -0.119398 0 -0 0</wrench>
        </link>
        <link name='rear_right_wheel'>
          <pose frame=''>-5.48066 -5.67863 -0.36291 0.003309 0.884655 -0.048214</pose>
          <velocity>0.011441 -0.000716 0.029852 -0.003469 -0.033682 0.000681</velocity>
          <acceleration>0.069896 0.208909 -0.018243 -0.828722 0.287201 0.033662</acceleration>
          <wrench>0.139793 0.417818 -0.036486 0 -0 0</wrench>
        </link>
        <link name='right_aileron'>
          <pose frame=''>-4.90308 -5.60428 1.62451 0.062487 -0.526675 -0.040583</pose>
          <velocity>-0.002543 -0.001095 -0.000468 0.001854 0.006079 0.000573</velocity>
          <acceleration>0.132227 0.337418 0.735163 -0.040196 -1.02427 0.08255</acceleration>
          <wrench>0.264453 0.674837 1.47033 0 -0 0</wrench>
        </link>
        <link name='right_flap'>
          <pose frame=''>-4.82076 -5.6939 1.49336 -0.002762 -0.530577 -0.039274</pose>
          <velocity>0.010906 0.000192 0.075318 0.000254 -0.030088 0.001344</velocity>
          <acceleration>3.50652 0.037213 -5.16791 2.58195 -0.075263 0.743569</acceleration>
          <wrench>7.01305 0.074426 -10.3358 0 -0 0</wrench>
        </link>
        <link name='rudder'>
          <pose frame=''>-5.30882 -5.70317 0.4924 0.001337 -0.000651 -0.053432</pose>
          <velocity>-0.005112 0.031728 0.005656 -7.1e-05 0.00419 0.006317</velocity>
          <acceleration>-0.060292 0.076322 -0.067889 -0.220381 -0.125235 0.45073</acceleration>
          <wrench>-0.120585 0.152644 -0.135779 0 -0 0</wrench>
        </link>
      </model>
      <model name='coke_can'>
        <pose frame=''>0.430516 -7.64105 1.01243 -0.008989 0.003207 -0.108562</pose>
        <scale>1 1 1</scale>
        <link name='link'>
          <pose frame=''>0.430516 -7.64105 1.01243 -0.008989 0.003207 -0.108562</pose>
          <velocity>0 0 0 0 -0 0</velocity>
          <acceleration>-0.040005 -0.207595 0.029332 -2.67468 -0.697813 -0.348439</acceleration>
          <wrench>-0.015602 -0.080962 0.011439 0 -0 0</wrench>
        </link>
      </model>
      <model name='coke_can_0'>
        <pose frame=''>0.870953 -7.75876 1.01243 -0.010767 0.003851 0.029017</pose>
        <scale>1 1 1</scale>
        <link name='link'>
          <pose frame=''>0.870953 -7.75876 1.01243 -0.010767 0.003851 0.029017</pose>
          <velocity>0 0 0 0 -0 0</velocity>
          <acceleration>-0.002146 0.303885 -0.006244 0.990349 -0.039898 -0.156177</acceleration>
          <wrench>-0.000837 0.118515 -0.002435 0 -0 0</wrench>
        </link>
      </model>
      <model name='door'>
        <pose frame=''>0.011495 -1.74221 1e-06 1.5708 -0 0</pose>
        <scale>1 1 1</scale>
        <link name='door_body'>
          <pose frame=''>0.017081 -1.73627 2e-06 1.5708 1e-06 -0.082166</pose>
          <velocity>-0.000141 3.1e-05 8.5e-05 4e-06 3e-05 2e-06</velocity>
          <acceleration>-0.216654 0.147919 0.138565 0.009762 0.060124 0.217721</acceleration>
          <wrench>-0.216654 0.147919 0.138565 0 -0 0</wrench>
        </link>
        <link name='door_frame'>
          <pose frame=''>0.011495 -1.74221 1e-06 1.5708 -0 0</pose>
          <velocity>0 1e-06 3e-06 -5e-06 -1.4e-05 -1e-06</velocity>
          <acceleration>-0.029155 0.00992 0.022552 -0.007992 -0.029312 -0.001343</acceleration>
          <wrench>-0.874641 0.297595 0.676573 0 -0 0</wrench>
        </link>
        <link name='door_handle'>
          <pose frame=''>0.01708 -1.73627 2e-06 1.5708 -0 -0.082166</pose>
          <velocity>-0.000185 6.1e-05 0.000123 -2e-06 -0 -0.000145</velocity>
          <acceleration>-0.410222 0.012167 0.247092 -0.003189 -0.000203 -0.12617</acceleration>
          <wrench>-0.410222 0.012167 0.247092 0 -0 0</wrench>
        </link>
      </model>
      <model name='frc2016_ball'>
        <pose frame=''>2.26823 -7.5874 1.14183 0 -0 0</pose>
        <scale>1 1 1</scale>
        <link name='link'>
          <pose frame=''>2.26823 -7.5874 1.14183 0 -0 0</pose>
          <velocity>0 0 0 0 -0 0</velocity>
          <acceleration>0 0 0 0 -0 0</acceleration>
          <wrench>0 0 0 0 -0 0</wrench>
        </link>
      </model>
      <model name='ground_plane'>
        <pose frame=''>0 0 0 0 -0 0</pose>
        <scale>1 1 1</scale>
        <link name='link'>
          <pose frame=''>0 0 0 0 -0 0</pose>
          <velocity>0 0 0 0 -0 0</velocity>
          <acceleration>0 0 0 0 -0 0</acceleration>
          <wrench>0 0 0 0 -0 0</wrench>
        </link>
      </model>
      <model name='saucepan'>
        <pose frame=''>2.57351 -7.80551 1.044 3e-06 5.6e-05 0.00407</pose>
        <scale>1 1 1</scale>
        <link name='link'>
          <pose frame=''>2.57351 -7.80551 1.044 3e-06 5.6e-05 0.00407</pose>
          <velocity>0 0 0 0 -0 0</velocity>
          <acceleration>0 0 -9.8 0 -0 0</acceleration>
          <wrench>0 0 -0.98 0 -0 0</wrench>
        </link>
      </model>
      <model name='table'>
        <pose frame=''>2.37957 -7.56738 0 0 -0 0</pose>
        <scale>1 1 1</scale>
        <link name='link'>
          <pose frame=''>2.37957 -7.56738 0 0 -0 0</pose>
          <velocity>0 0 0 0 -0 0</velocity>
          <acceleration>0 0 0 0 -0 0</acceleration>
          <wrench>0 0 0 0 -0 0</wrench>
        </link>
      </model>
      <model name='table_0'>
        <pose frame=''>0.867841 -7.56377 0 0 -0 0</pose>
        <scale>1 1 1</scale>
        <link name='link'>
          <pose frame=''>0.867841 -7.56377 0 0 -0 0</pose>
          <velocity>0 0 0 0 -0 0</velocity>
          <acceleration>0 0 0 0 -0 0</acceleration>
          <wrench>0 0 0 0 -0 0</wrench>
        </link>
      </model>
      <model name='turtlebot'>
        <pose frame=''>1.31864 -7.56938 1.01582 0.000188 -0.021589 0.005989</pose>
        <scale>1 1 1</scale>
        <link name='create::base'>
          <pose frame=''>1.31864 -7.56938 1.01582 0.000188 -0.021589 0.005989</pose>
          <velocity>0.000309 -0.000117 -0.007537 0.000306 -0.003132 0.000768</velocity>
          <acceleration>-0.001125 -0.001713 -9.81825 0.086086 -0.061682 -0.006313</acceleration>
          <wrench>-0.002514 -0.003827 -21.934 0 -0 0</wrench>
        </link>
        <link name='create::left_wheel'>
          <pose frame=''>1.31717 -7.43939 1.04797 0.000261 -0.672736 0.005831</pose>
          <velocity>0.000108 -0.000134 -0.042024 -0.003687 0.002898 0.000769</velocity>
          <acceleration>0.002443 -0.040709 -67.2107 -0.217302 -0.038951 -0.00884</acceleration>
          <wrench>2.4e-05 -0.000407 -0.672107 0 -0 0</wrench>
        </link>
        <link name='create::right_wheel'>
          <pose frame=''>1.31873 -7.69938 1.04797 0.000248 -0.599083 0.005853</pose>
          <velocity>0.000309 -0.000127 -0.053058 -0.003896 0.009231 0.000792</velocity>
          <acceleration>-0.005135 -0.04404 -82.0677 -0.116309 -0.038353 0.029261</acceleration>
          <wrench>-5.1e-05 -0.00044 -0.820677 0 -0 0</wrench>
        </link>
        <link name='kinect::link'>
          <pose frame=''>1.22501 -7.56999 1.31772 0.000189 -0.021589 0.005989</pose>
          <velocity>-0.000624 -0.00025 -0.007285 0.000172 -0.003095 0.000901</velocity>
          <acceleration>0.001703 0.006821 -8.9402 -0.013854 -0.000661 0.014144</acceleration>
          <wrench>0.00017 0.000682 -0.89402 0 -0 0</wrench>
        </link>
        <link name='rack'>
          <pose frame=''>1.31864 -7.56938 1.01582 0.000188 -0.021589 0.005989</pose>
          <velocity>0.00031 -0.000115 -0.00718 0.000248 -0.003116 0.000826</velocity>
          <acceleration>0.001061 0.001787 -9.23976 0.045934 -0.033871 0.002552</acceleration>
          <wrench>0.002371 0.003992 -20.6416 0 -0 0</wrench>
        </link>
      </model>
      <light name='sun'>
        <pose frame=''>0 0 10 0 -0 0</pose>
      </light>
    </state>
    <gui fullscreen='0'>
      <camera name='user_camera'>
        <pose frame=''>0.650367 9.1881 15.1533 0 0.765797 -1.57262</pose>
        <view_controller>orbit</view_controller>
        <projection_type>perspective</projection_type>
      </camera>
    </gui>
    <model name='table_0'>
      <static>1</static>
      <link name='link'>
        <collision name='surface'>
          <pose frame=''>0 0 1 0 -0 0</pose>
          <geometry>
            <box>
              <size>1.5 0.8 0.03</size>
            </box>
          </geometry>
          <surface>
            <friction>
              <ode>
                <mu>0.6</mu>
                <mu2>0.6</mu2>
              </ode>
              <torsional>
                <ode/>
              </torsional>
            </friction>
            <contact>
              <ode/>
            </contact>
            <bounce/>
          </surface>
          <max_contacts>10</max_contacts>
        </collision>
        <visual name='visual1'>
          <pose frame=''>0 0 1 0 -0 0</pose>
          <geometry>
            <box>
              <size>1.5 0.8 0.03</size>
            </box>
          </geometry>
          <material>
            <script>
              <uri>file://media/materials/scripts/gazebo.material</uri>
              <name>Gazebo/Wood</name>
            </script>
          </material>
        </visual>
        <collision name='front_left_leg'>
          <pose frame=''>0.68 0.38 0.5 0 -0 0</pose>
          <geometry>
            <cylinder>
              <radius>0.02</radius>
              <length>1</length>
            </cylinder>
          </geometry>
          <max_contacts>10</max_contacts>
          <surface>
            <contact>
              <ode/>
            </contact>
            <bounce/>
            <friction>
              <torsional>
                <ode/>
              </torsional>
              <ode/>
            </friction>
          </surface>
        </collision>
        <visual name='front_left_leg'>
          <pose frame=''>0.68 0.38 0.5 0 -0 0</pose>
          <geometry>
            <cylinder>
              <radius>0.02</radius>
              <length>1</length>
            </cylinder>
          </geometry>
          <material>
            <script>
              <uri>file://media/materials/scripts/gazebo.material</uri>
              <name>Gazebo/Grey</name>
            </script>
          </material>
        </visual>
        <collision name='front_right_leg'>
          <pose frame=''>0.68 -0.38 0.5 0 -0 0</pose>
          <geometry>
            <cylinder>
              <radius>0.02</radius>
              <length>1</length>
            </cylinder>
          </geometry>
          <max_contacts>10</max_contacts>
          <surface>
            <contact>
              <ode/>
            </contact>
            <bounce/>
            <friction>
              <torsional>
                <ode/>
              </torsional>
              <ode/>
            </friction>
          </surface>
        </collision>
        <visual name='front_right_leg'>
          <pose frame=''>0.68 -0.38 0.5 0 -0 0</pose>
          <geometry>
            <cylinder>
              <radius>0.02</radius>
              <length>1</length>
            </cylinder>
          </geometry>
          <material>
            <script>
              <uri>file://media/materials/scripts/gazebo.material</uri>
              <name>Gazebo/Grey</name>
            </script>
          </material>
        </visual>
        <collision name='back_right_leg'>
          <pose frame=''>-0.68 -0.38 0.5 0 -0 0</pose>
          <geometry>
            <cylinder>
              <radius>0.02</radius>
              <length>1</length>
            </cylinder>
          </geometry>
          <max_contacts>10</max_contacts>
          <surface>
            <contact>
              <ode/>
            </contact>
            <bounce/>
            <friction>
              <torsional>
                <ode/>
              </torsional>
              <ode/>
            </friction>
          </surface>
        </collision>
        <visual name='back_right_leg'>
          <pose frame=''>-0.68 -0.38 0.5 0 -0 0</pose>
          <geometry>
            <cylinder>
              <radius>0.02</radius>
              <length>1</length>
            </cylinder>
          </geometry>
          <material>
            <script>
              <uri>file://media/materials/scripts/gazebo.material</uri>
              <name>Gazebo/Grey</name>
            </script>
          </material>
        </visual>
        <collision name='back_left_leg'>
          <pose frame=''>-0.68 0.38 0.5 0 -0 0</pose>
          <geometry>
            <cylinder>
              <radius>0.02</radius>
              <length>1</length>
            </cylinder>
          </geometry>
          <max_contacts>10</max_contacts>
          <surface>
            <contact>
              <ode/>
            </contact>
            <bounce/>
            <friction>
              <torsional>
                <ode/>
              </torsional>
              <ode/>
            </friction>
          </surface>
        </collision>
        <visual name='back_left_leg'>
          <pose frame=''>-0.68 0.38 0.5 0 -0 0</pose>
          <geometry>
            <cylinder>
              <radius>0.02</radius>
              <length>1</length>
            </cylinder>
          </geometry>
          <material>
            <script>
              <uri>file://media/materials/scripts/gazebo.material</uri>
              <name>Gazebo/Grey</name>
            </script>
          </material>
        </visual>
        <self_collide>0</self_collide>
        <kinematic>0</kinematic>
      </link>
      <pose frame=''>0.867841 -7.56377 0 0 -0 0</pose>
    </model>
    <model name='Mailbox'>
      <link name='link'>
        <collision name='collision'>
          <geometry>
            <mesh>
              <uri>model://mailbox/meshes/mailbox.dae</uri>
            </mesh>
          </geometry>
          <max_contacts>10</max_contacts>
          <surface>
            <contact>
              <ode/>
            </contact>
            <bounce/>
            <friction>
              <torsional>
                <ode/>
              </torsional>
              <ode/>
            </friction>
          </surface>
        </collision>
        <visual name='visual'>
          <geometry>
            <mesh>
              <uri>model://mailbox/meshes/mailbox.dae</uri>
            </mesh>
          </geometry>
          <material>
            <script>
              <uri>model://mailbox/materials/scripts</uri>
              <uri>model://mailbox/materials/textures</uri>
              <name>Mailbox/Diffuse</name>
            </script>
          </material>
        </visual>
        <self_collide>0</self_collide>
        <inertial>
          <inertia>
            <ixx>1</ixx>
            <ixy>0</ixy>
            <ixz>0</ixz>
            <iyy>1</iyy>
            <iyz>0</iyz>
            <izz>1</izz>
          </inertia>
          <mass>1</mass>
        </inertial>
        <kinematic>0</kinematic>
      </link>
      <pose frame=''>2.6856 -0.115523 0 0 -0 0</pose>
    </model>
    <model name='table'>
      <static>1</static>
      <link name='link'>
        <collision name='surface'>
          <pose frame=''>0 0 1 0 -0 0</pose>
          <geometry>
            <box>
              <size>1.5 0.8 0.03</size>
            </box>
          </geometry>
          <surface>
            <friction>
              <ode>
                <mu>0.6</mu>
                <mu2>0.6</mu2>
              </ode>
              <torsional>
                <ode/>
              </torsional>
            </friction>
            <contact>
              <ode/>
            </contact>
            <bounce/>
          </surface>
          <max_contacts>10</max_contacts>
        </collision>
        <visual name='visual1'>
          <pose frame=''>0 0 1 0 -0 0</pose>
          <geometry>
            <box>
              <size>1.5 0.8 0.03</size>
            </box>
          </geometry>
          <material>
            <script>
              <uri>file://media/materials/scripts/gazebo.material</uri>
              <name>Gazebo/Wood</name>
            </script>
          </material>
        </visual>
        <collision name='front_left_leg'>
          <pose frame=''>0.68 0.38 0.5 0 -0 0</pose>
          <geometry>
            <cylinder>
              <radius>0.02</radius>
              <length>1</length>
            </cylinder>
          </geometry>
          <max_contacts>10</max_contacts>
          <surface>
            <contact>
              <ode/>
            </contact>
            <bounce/>
            <friction>
              <torsional>
                <ode/>
              </torsional>
              <ode/>
            </friction>
          </surface>
        </collision>
        <visual name='front_left_leg'>
          <pose frame=''>0.68 0.38 0.5 0 -0 0</pose>
          <geometry>
            <cylinder>
              <radius>0.02</radius>
              <length>1</length>
            </cylinder>
          </geometry>
          <material>
            <script>
              <uri>file://media/materials/scripts/gazebo.material</uri>
              <name>Gazebo/Grey</name>
            </script>
          </material>
        </visual>
        <collision name='front_right_leg'>
          <pose frame=''>0.68 -0.38 0.5 0 -0 0</pose>
          <geometry>
            <cylinder>
              <radius>0.02</radius>
              <length>1</length>
            </cylinder>
          </geometry>
          <max_contacts>10</max_contacts>
          <surface>
            <contact>
              <ode/>
            </contact>
            <bounce/>
            <friction>
              <torsional>
                <ode/>
              </torsional>
              <ode/>
            </friction>
          </surface>
        </collision>
        <visual name='front_right_leg'>
          <pose frame=''>0.68 -0.38 0.5 0 -0 0</pose>
          <geometry>
            <cylinder>
              <radius>0.02</radius>
              <length>1</length>
            </cylinder>
          </geometry>
          <material>
            <script>
              <uri>file://media/materials/scripts/gazebo.material</uri>
              <name>Gazebo/Grey</name>
            </script>
          </material>
        </visual>
        <collision name='back_right_leg'>
          <pose frame=''>-0.68 -0.38 0.5 0 -0 0</pose>
          <geometry>
            <cylinder>
              <radius>0.02</radius>
              <length>1</length>
            </cylinder>
          </geometry>
          <max_contacts>10</max_contacts>
          <surface>
            <contact>
              <ode/>
            </contact>
            <bounce/>
            <friction>
              <torsional>
                <ode/>
              </torsional>
              <ode/>
            </friction>
          </surface>
        </collision>
        <visual name='back_right_leg'>
          <pose frame=''>-0.68 -0.38 0.5 0 -0 0</pose>
          <geometry>
            <cylinder>
              <radius>0.02</radius>
              <length>1</length>
            </cylinder>
          </geometry>
          <material>
            <script>
              <uri>file://media/materials/scripts/gazebo.material</uri>
              <name>Gazebo/Grey</name>
            </script>
          </material>
        </visual>
        <collision name='back_left_leg'>
          <pose frame=''>-0.68 0.38 0.5 0 -0 0</pose>
          <geometry>
            <cylinder>
              <radius>0.02</radius>
              <length>1</length>
            </cylinder>
          </geometry>
          <max_contacts>10</max_contacts>
          <surface>
            <contact>
              <ode/>
            </contact>
            <bounce/>
            <friction>
              <torsional>
                <ode/>
              </torsional>
              <ode/>
            </friction>
          </surface>
        </collision>
        <visual name='back_left_leg'>
          <pose frame=''>-0.68 0.38 0.5 0 -0 0</pose>
          <geometry>
            <cylinder>
              <radius>0.02</radius>
              <length>1</length>
            </cylinder>
          </geometry>
          <material>
            <script>
              <uri>file://media/materials/scripts/gazebo.material</uri>
              <name>Gazebo/Grey</name>
            </script>
          </material>
        </visual>
        <self_collide>0</self_collide>
        <kinematic>0</kinematic>
      </link>
      <pose frame=''>2.37957 -7.56738 0 0 -0 0</pose>
    </model>
    <model name='frc2016_ball'>
      <pose frame=''>1.60423 -8.38651 0.127 0 -0 0</pose>
      <link name='link'>
        <inertial>
          <mass>0.213</mass>
          <inertia>
            <ixx>0.00322667</ixx>
            <ixy>0</ixy>
            <ixz>0</ixz>
            <iyy>0.00322667</iyy>
            <iyz>0</iyz>
            <izz>0.00322667</izz>
          </inertia>
        </inertial>
        <visual name='visual'>
          <geometry>
            <sphere>
              <radius>0.127</radius>
            </sphere>
          </geometry>
        </visual>
        <collision name='collision'>
          <geometry>
            <sphere>
              <radius>0.127</radius>
            </sphere>
          </geometry>
          <surface>
            <bounce>
              <restitution_coefficient>0.15937</restitution_coefficient>
              <threshold>0</threshold>
            </bounce>
            <contact>
              <ode>
                <max_vel>100</max_vel>
                <min_depth>0.001</min_depth>
              </ode>
            </contact>
            <friction>
              <torsional>
                <ode/>
              </torsional>
              <ode/>
            </friction>
          </surface>
          <max_contacts>10</max_contacts>
        </collision>
        <self_collide>0</self_collide>
        <kinematic>0</kinematic>
      </link>
    </model>
    <model name='turtlebot'>
      <link name='rack'>
        <inertial>
          <pose frame=''>0.001453 -0.000453 0.029787 0 -0 0</pose>
          <inertia>
            <ixx>0.05864</ixx>
            <ixy>0.000124</ixy>
            <ixz>0.000615</ixz>
            <iyy>0.058786</iyy>
            <iyz>1.4e-05</iyz>
            <izz>1.53244</izz>
          </inertia>
          <mass>2.234</mass>
        </inertial>
        <collision name='plate_0_collision'>
          <pose frame=''>-0.04334 0 0.084757 0 -0 0</pose>
          <geometry>
            <box>
              <size>0.233502 0.314845 0.006401</size>
            </box>
          </geometry>
          <max_contacts>10</max_contacts>
          <surface>
            <contact>
              <ode/>
            </contact>
            <bounce/>
            <friction>
              <torsional>
                <ode/>
              </torsional>
              <ode/>
            </friction>
          </surface>
        </collision>
        <visual name='plate_0_visual'>
          <pose frame=''>-0.04334 0 0.084757 0 -0 0</pose>
          <geometry>
            <mesh>
              <uri>model://turtlebot/meshes/plate_0_logo.dae</uri>
            </mesh>
          </geometry>
        </visual>
        <collision name='plate_1_collision'>
          <pose frame=''>-0.00266 0 0.141907 0 -0 0</pose>
          <geometry>
            <box>
              <size>0.314856 0.314856 0.006401</size>
            </box>
          </geometry>
          <max_contacts>10</max_contacts>
          <surface>
            <contact>
              <ode/>
            </contact>
            <bounce/>
            <friction>
              <torsional>
                <ode/>
              </torsional>
              <ode/>
            </friction>
          </surface>
        </collision>
        <visual name='plate_1_visual'>
          <pose frame=''>-0.00266 0 0.141907 0 -0 0</pose>
          <geometry>
            <mesh>
              <uri>model://turtlebot/meshes/plate_1_logo.dae</uri>
            </mesh>
          </geometry>
        </visual>
        <collision name='plate_2_collision'>
          <pose frame=''>-0.00266 0 0.199108 0 -0 0</pose>
          <geometry>
            <box>
              <size>0.314856 0.314856 0.006401</size>
            </box>
          </geometry>
          <max_contacts>10</max_contacts>
          <surface>
            <contact>
              <ode/>
            </contact>
            <bounce/>
            <friction>
              <torsional>
                <ode/>
              </torsional>
              <ode/>
            </friction>
          </surface>
        </collision>
        <visual name='plate_2_visual'>
          <pose frame=''>-0.00266 0 0.199108 0 -0 0</pose>
          <geometry>
            <mesh>
              <uri>model://turtlebot/meshes/plate_1_logo.dae</uri>
            </mesh>
          </geometry>
        </visual>
        <collision name='plate_3_collision'>
          <pose frame=''>-0.01582 0 0.405457 0 -0 0</pose>
          <geometry>
            <box>
              <size>0.288 0.315 0.006401</size>
            </box>
          </geometry>
          <max_contacts>10</max_contacts>
          <surface>
            <contact>
              <ode/>
            </contact>
            <bounce/>
            <friction>
              <torsional>
                <ode/>
              </torsional>
              <ode/>
            </friction>
          </surface>
        </collision>
        <visual name='plate_3_visual'>
          <pose frame=''>-0.01582 0 0.405457 0 -0 0</pose>
          <geometry>
            <mesh>
              <uri>model://turtlebot/meshes/plate_2_logo.dae</uri>
            </mesh>
          </geometry>
        </visual>
        <collision name='spacer_0_collision'>
          <pose frame=''>-0.00254 0.111468 0.079992 0 -0 0</pose>
          <geometry>
            <cylinder>
              <radius>0.0127</radius>
              <length>0.003175</length>
            </cylinder>
          </geometry>
          <max_contacts>10</max_contacts>
          <surface>
            <contact>
              <ode/>
            </contact>
            <bounce/>
            <friction>
              <torsional>
                <ode/>
              </torsional>
              <ode/>
            </friction>
          </surface>
        </collision>
        <visual name='spacer_0_visual'>
          <pose frame=''>-0.00254 0.111468 0.079992 0 -0 0</pose>
          <geometry>
            <mesh>
              <uri>model://turtlebot/meshes/68-02403-125_Spacer.dae</uri>
            </mesh>
          </geometry>
        </visual>
        <collision name='spacer_1_collision'>
          <pose frame=''>-0.00254 -0.111468 0.079992 0 -0 0</pose>
          <geometry>
            <cylinder>
              <radius>0.0127</radius>
              <length>0.003175</length>
            </cylinder>
          </geometry>
          <max_contacts>10</max_contacts>
          <surface>
            <contact>
              <ode/>
            </contact>
            <bounce/>
            <friction>
              <torsional>
                <ode/>
              </torsional>
              <ode/>
            </friction>
          </surface>
        </collision>
        <visual name='spacer_1_visual'>
          <pose frame=''>-0.00254 -0.111468 0.079992 0 -0 0</pose>
          <geometry>
            <mesh>
              <uri>model://turtlebot/meshes/68-02403-125_Spacer.dae</uri>
            </mesh>
          </geometry>
        </visual>
        <collision name='spacer_2_collision'>
          <pose frame=''>-0.07239 -0.111468 0.079992 0 -0 0</pose>
          <geometry>
            <cylinder>
              <radius>0.0127</radius>
              <length>0.003175</length>
            </cylinder>
          </geometry>
          <max_contacts>10</max_contacts>
          <surface>
            <contact>
              <ode/>
            </contact>
            <bounce/>
            <friction>
              <torsional>
                <ode/>
              </torsional>
              <ode/>
            </friction>
          </surface>
        </collision>
        <visual name='spacer_2_visual'>
          <pose frame=''>-0.07239 -0.111468 0.079992 0 -0 0</pose>
          <geometry>
            <mesh>
              <uri>model://turtlebot/meshes/68-02403-125_Spacer.dae</uri>
            </mesh>
          </geometry>
        </visual>
        <collision name='spacer_3_collision'>
          <pose frame=''>-0.07239 0.111468 0.079992 0 -0 0</pose>
          <geometry>
            <cylinder>
              <radius>0.0127</radius>
              <length>0.003175</length>
            </cylinder>
          </geometry>
          <max_contacts>10</max_contacts>
          <surface>
            <contact>
              <ode/>
            </contact>
            <bounce/>
            <friction>
              <torsional>
                <ode/>
              </torsional>
              <ode/>
            </friction>
          </surface>
        </collision>
        <visual name='spacer_3_visual'>
          <pose frame=''>-0.07239 0.111468 0.079992 0 -0 0</pose>
          <geometry>
            <mesh>
              <uri>model://turtlebot/meshes/68-02403-125_Spacer.dae</uri>
            </mesh>
          </geometry>
        </visual>
        <collision name='standoff_2in_0_collision'>
          <pose frame=''>0.06764 0.13142 0.08798 0 -0 0</pose>
          <geometry>
            <cylinder>
              <radius>0.0381</radius>
              <length>0.0635</length>
            </cylinder>
          </geometry>
          <max_contacts>10</max_contacts>
          <surface>
            <contact>
              <ode/>
            </contact>
            <bounce/>
            <friction>
              <torsional>
                <ode/>
              </torsional>
              <ode/>
            </friction>
          </surface>
        </collision>
        <visual name='standoff_2in_0_visual'>
          <pose frame=''>0.06764 0.13142 0.08798 0 -0 0</pose>
          <geometry>
            <mesh>
              <uri>model://turtlebot/meshes/68-04552-2000-RA_Turtlebot_M-F_Standoff.dae</uri>
            </mesh>
          </geometry>
        </visual>
        <collision name='standoff_2in_1_collision'>
          <pose frame=''>0.06764 -0.13142 0.08798 0 -0 0</pose>
          <geometry>
            <cylinder>
              <radius>0.0381</radius>
              <length>0.0635</length>
            </cylinder>
          </geometry>
          <max_contacts>10</max_contacts>
          <surface>
            <contact>
              <ode/>
            </contact>
            <bounce/>
            <friction>
              <torsional>
                <ode/>
              </torsional>
              <ode/>
            </friction>
          </surface>
        </collision>
        <visual name='standoff_2in_1_visual'>
          <pose frame=''>0.06764 -0.13142 0.08798 0 -0 0</pose>
          <geometry>
            <mesh>
              <uri>model://turtlebot/meshes/68-04552-2000-RA_Turtlebot_M-F_Standoff.dae</uri>
            </mesh>
          </geometry>
        </visual>
        <collision name='standoff_2in_2_collision'>
          <pose frame=''>-0.052832 -0.13142 0.08798 0 -0 0</pose>
          <geometry>
            <cylinder>
              <radius>0.0381</radius>
              <length>0.0635</length>
            </cylinder>
          </geometry>
          <max_contacts>10</max_contacts>
          <surface>
            <contact>
              <ode/>
            </contact>
            <bounce/>
            <friction>
              <torsional>
                <ode/>
              </torsional>
              <ode/>
            </friction>
          </surface>
        </collision>
        <visual name='standoff_2in_2_visual'>
          <pose frame=''>-0.052832 -0.13142 0.08798 0 -0 0</pose>
          <geometry>
            <mesh>
              <uri>model://turtlebot/meshes/68-04552-2000-RA_Turtlebot_M-F_Standoff.dae</uri>
            </mesh>
          </geometry>
        </visual>
        <collision name='standoff_2in_3_collision'>
          <pose frame=''>-0.052832 0.13142 0.08798 0 -0 0</pose>
          <geometry>
            <cylinder>
              <radius>0.0381</radius>
              <length>0.0635</length>
            </cylinder>
          </geometry>
          <max_contacts>10</max_contacts>
          <surface>
            <contact>
              <ode/>
            </contact>
            <bounce/>
            <friction>
              <torsional>
                <ode/>
              </torsional>
              <ode/>
            </friction>
          </surface>
        </collision>
        <visual name='standoff_2in_3_visual'>
          <pose frame=''>-0.052832 0.13142 0.08798 0 -0 0</pose>
          <geometry>
            <mesh>
              <uri>model://turtlebot/meshes/68-04552-2000-RA_Turtlebot_M-F_Standoff.dae</uri>
            </mesh>
          </geometry>
        </visual>
        <collision name='standoff_2in_4_collision'>
          <pose frame=''>0.06764 0.13142 0.14513 0 -0 0</pose>
          <geometry>
            <cylinder>
              <radius>0.0381</radius>
              <length>0.0635</length>
            </cylinder>
          </geometry>
          <max_contacts>10</max_contacts>
          <surface>
            <contact>
              <ode/>
            </contact>
            <bounce/>
            <friction>
              <torsional>
                <ode/>
              </torsional>
              <ode/>
            </friction>
          </surface>
        </collision>
        <visual name='standoff_2in_4_visual'>
          <pose frame=''>0.06764 0.13142 0.14513 0 -0 0</pose>
          <geometry>
            <mesh>
              <uri>model://turtlebot/meshes/68-04552-2000-RA_Turtlebot_M-F_Standoff.dae</uri>
            </mesh>
          </geometry>
        </visual>
        <collision name='standoff_2in_5_collision'>
          <pose frame=''>0.06764 -0.13142 0.14513 0 -0 0</pose>
          <geometry>
            <cylinder>
              <radius>0.0381</radius>
              <length>0.0635</length>
            </cylinder>
          </geometry>
          <max_contacts>10</max_contacts>
          <surface>
            <contact>
              <ode/>
            </contact>
            <bounce/>
            <friction>
              <torsional>
                <ode/>
              </torsional>
              <ode/>
            </friction>
          </surface>
        </collision>
        <visual name='standoff_2in_5_visual'>
          <pose frame=''>0.06764 -0.13142 0.14513 0 -0 0</pose>
          <geometry>
            <mesh>
              <uri>model://turtlebot/meshes/68-04552-2000-RA_Turtlebot_M-F_Standoff.dae</uri>
            </mesh>
          </geometry>
        </visual>
        <collision name='standoff_2in_6_collision'>
          <pose frame=''>-0.052832 -0.13142 0.14513 0 -0 0</pose>
          <geometry>
            <cylinder>
              <radius>0.0381</radius>
              <length>0.0635</length>
            </cylinder>
          </geometry>
          <max_contacts>10</max_contacts>
          <surface>
            <contact>
              <ode/>
            </contact>
            <bounce/>
            <friction>
              <torsional>
                <ode/>
              </torsional>
              <ode/>
            </friction>
          </surface>
        </collision>
        <visual name='standoff_2in_6_visual'>
          <pose frame=''>-0.052832 -0.13142 0.14513 0 -0 0</pose>
          <geometry>
            <mesh>
              <uri>model://turtlebot/meshes/68-04552-2000-RA_Turtlebot_M-F_Standoff.dae</uri>
            </mesh>
          </geometry>
        </visual>
        <collision name='standoff_2in_7_collision'>
          <pose frame=''>-0.052832 0.13142 0.14513 0 -0 0</pose>
          <geometry>
            <cylinder>
              <radius>0.0381</radius>
              <length>0.0635</length>
            </cylinder>
          </geometry>
          <max_contacts>10</max_contacts>
          <surface>
            <contact>
              <ode/>
            </contact>
            <bounce/>
            <friction>
              <torsional>
                <ode/>
              </torsional>
              <ode/>
            </friction>
          </surface>
        </collision>
        <visual name='standoff_2in_7_visual'>
          <pose frame=''>-0.052832 0.13142 0.14513 0 -0 0</pose>
          <geometry>
            <mesh>
              <uri>model://turtlebot/meshes/68-04552-2000-RA_Turtlebot_M-F_Standoff.dae</uri>
            </mesh>
          </geometry>
        </visual>
        <collision name='standoff_8in_0_collision'>
          <pose frame=''>0.06764 0.13142 0.20228 0 -0 0</pose>
          <geometry>
            <cylinder>
              <radius>0.011113</radius>
              <length>0.2032</length>
            </cylinder>
          </geometry>
          <max_contacts>10</max_contacts>
          <surface>
            <contact>
              <ode/>
            </contact>
            <bounce/>
            <friction>
              <torsional>
                <ode/>
              </torsional>
              <ode/>
            </friction>
          </surface>
        </collision>
        <visual name='standoff_8in_0_visual'>
          <pose frame=''>0.06764 0.13142 0.20228 0 -0 0</pose>
          <geometry>
            <mesh>
              <uri>model://turtlebot/meshes/68-02421-8000-RA_Turtlebot_F-F_Standoff.dae</uri>
            </mesh>
          </geometry>
        </visual>
        <collision name='standoff_8in_1_collision'>
          <pose frame=''>0.06764 -0.13142 0.20228 0 -0 0</pose>
          <geometry>
            <cylinder>
              <radius>0.011113</radius>
              <length>0.2032</length>
            </cylinder>
          </geometry>
          <max_contacts>10</max_contacts>
          <surface>
            <contact>
              <ode/>
            </contact>
            <bounce/>
            <friction>
              <torsional>
                <ode/>
              </torsional>
              <ode/>
            </friction>
          </surface>
        </collision>
        <visual name='standoff_8in_1_visual'>
          <pose frame=''>0.06764 -0.13142 0.20228 0 -0 0</pose>
          <geometry>
            <mesh>
              <uri>model://turtlebot/meshes/68-02421-8000-RA_Turtlebot_F-F_Standoff.dae</uri>
            </mesh>
          </geometry>
        </visual>
        <collision name='standoff_8in_2_collision'>
          <pose frame=''>-0.052832 -0.13142 0.20228 0 -0 0</pose>
          <geometry>
            <cylinder>
              <radius>0.011113</radius>
              <length>0.2032</length>
            </cylinder>
          </geometry>
          <max_contacts>10</max_contacts>
          <surface>
            <contact>
              <ode/>
            </contact>
            <bounce/>
            <friction>
              <torsional>
                <ode/>
              </torsional>
              <ode/>
            </friction>
          </surface>
        </collision>
        <visual name='standoff_8in_2_visual'>
          <pose frame=''>-0.052832 -0.13142 0.20228 0 -0 0</pose>
          <geometry>
            <mesh>
              <uri>model://turtlebot/meshes/68-02421-8000-RA_Turtlebot_F-F_Standoff.dae</uri>
            </mesh>
          </geometry>
        </visual>
        <collision name='standoff_8in_3_collision'>
          <pose frame=''>-0.052832 0.13142 0.20228 0 -0 0</pose>
          <geometry>
            <cylinder>
              <radius>0.011113</radius>
              <length>0.2032</length>
            </cylinder>
          </geometry>
          <max_contacts>10</max_contacts>
          <surface>
            <contact>
              <ode/>
            </contact>
            <bounce/>
            <friction>
              <torsional>
                <ode/>
              </torsional>
              <ode/>
            </friction>
          </surface>
        </collision>
        <visual name='standoff_8in_3_visual'>
          <pose frame=''>-0.052832 0.13142 0.20228 0 -0 0</pose>
          <geometry>
            <mesh>
              <uri>model://turtlebot/meshes/68-02421-8000-RA_Turtlebot_F-F_Standoff.dae</uri>
            </mesh>
          </geometry>
        </visual>
        <collision name='standoff_kinect_0_collision'>
          <pose frame=''>-0.105098 0.098 0.202308 0 -0 0</pose>
          <geometry>
            <cylinder>
              <radius>0.001111</radius>
              <length>0.008585</length>
            </cylinder>
          </geometry>
          <max_contacts>10</max_contacts>
          <surface>
            <contact>
              <ode/>
            </contact>
            <bounce/>
            <friction>
              <torsional>
                <ode/>
              </torsional>
              <ode/>
            </friction>
          </surface>
        </collision>
        <visual name='standoff_kinect_0_visual'>
          <pose frame=''>-0.105098 0.098 0.202308 0 -0 0</pose>
          <geometry>
            <mesh>
              <uri>model://turtlebot/meshes/68-04556-RA_Kinect_Standoff_Assy.dae</uri>
            </mesh>
          </geometry>
        </visual>
        <collision name='standoff_kinect_1_collision'>
          <pose frame=''>-0.105098 -0.098 0.202308 0 -0 0</pose>
          <geometry>
            <cylinder>
              <radius>0.001111</radius>
              <length>0.008585</length>
            </cylinder>
          </geometry>
          <max_contacts>10</max_contacts>
          <surface>
            <contact>
              <ode/>
            </contact>
            <bounce/>
            <friction>
              <torsional>
                <ode/>
              </torsional>
              <ode/>
            </friction>
          </surface>
        </collision>
        <visual name='standoff_kinect_1_visual'>
          <pose frame=''>-0.105098 -0.098 0.202308 0 -0 0</pose>
          <geometry>
            <mesh>
              <uri>model://turtlebot/meshes/68-04556-RA_Kinect_Standoff_Assy.dae</uri>
            </mesh>
          </geometry>
        </visual>
        <sensor name='laser' type='ray'>
          <pose frame=''>-0.065 0 0.092 0 -0 0</pose>
          <ray>
            <scan>
              <horizontal>
                <samples>180</samples>
                <resolution>1</resolution>
                <min_angle>-2.26893</min_angle>
                <max_angle>2.26893</max_angle>
              </horizontal>
              <vertical>
                <samples>1</samples>
                <min_angle>0</min_angle>
                <max_angle>0</max_angle>
              </vertical>
            </scan>
            <range>
              <min>0.08</min>
              <max>10</max>
              <resolution>0.01</resolution>
            </range>
          </ray>
          <update_rate>20</update_rate>
        </sensor>
        <self_collide>0</self_collide>
        <kinematic>0</kinematic>
      </link>
      <link name='create::base'>
        <inertial>
          <pose frame=''>0.001453 -0.000453 0.029787 0 -0 0</pose>
          <inertia>
            <ixx>0.05864</ixx>
            <ixy>0.000124</ixy>
            <ixz>0.000615</ixz>
            <iyy>0.058786</iyy>
            <iyz>1.4e-05</iyz>
            <izz>1.53244</izz>
          </inertia>
          <mass>2.234</mass>
        </inertial>
        <collision name='base_collision'>
          <pose frame=''>0 0 0.0478 0 -0 0</pose>
          <geometry>
            <cylinder>
              <radius>0.016495</radius>
              <length>0.061163</length>
            </cylinder>
          </geometry>
          <max_contacts>10</max_contacts>
          <surface>
            <contact>
              <ode/>
            </contact>
            <bounce/>
            <friction>
              <torsional>
                <ode/>
              </torsional>
              <ode/>
            </friction>
          </surface>
        </collision>
        <visual name='base_visual'>
          <pose frame=''>0 0 0.0478 0 -0 0</pose>
          <geometry>
            <mesh>
              <uri>model://create/meshes/create_body.dae</uri>
            </mesh>
          </geometry>
        </visual>
        <collision name='front_wheel_collision'>
          <pose frame=''>0.13 0 0.017 -0 1.5707 1.5707</pose>
          <geometry>
            <sphere>
              <radius>0.018</radius>
            </sphere>
          </geometry>
          <surface>
            <friction>
              <ode>
                <mu>0</mu>
                <mu2>0</mu2>
                <fdir1>0 0 0</fdir1>
                <slip1>0</slip1>
                <slip2>0</slip2>
              </ode>
              <torsional>
                <ode/>
              </torsional>
            </friction>
            <contact>
              <ode/>
            </contact>
            <bounce/>
          </surface>
          <max_contacts>10</max_contacts>
        </collision>
        <visual name='front_wheel_visual'>
          <pose frame=''>0.13 0 0.017 -0 1.5707 1.5707</pose>
          <geometry>
            <sphere>
              <radius>0.009</radius>
            </sphere>
          </geometry>
        </visual>
        <collision name='rear_wheel_collision'>
          <pose frame=''>-0.13 0 0.017 -0 1.5707 1.5707</pose>
          <geometry>
            <sphere>
              <radius>0.015</radius>
            </sphere>
          </geometry>
          <surface>
            <friction>
              <ode>
                <mu>0</mu>
                <mu2>0</mu2>
                <fdir1>0 0 0</fdir1>
                <slip1>0</slip1>
                <slip2>0</slip2>
              </ode>
              <torsional>
                <ode/>
              </torsional>
            </friction>
            <contact>
              <ode/>
            </contact>
            <bounce/>
          </surface>
          <max_contacts>10</max_contacts>
        </collision>
        <visual name='rear_wheel_visual'>
          <pose frame=''>-0.13 0 0.017 -0 1.5707 1.5707</pose>
          <geometry>
            <sphere>
              <radius>0.0075</radius>
            </sphere>
          </geometry>
        </visual>
        <sensor name='left_cliff_sensor' type='ray'>
          <pose frame=''>0.07 0.14 0.027 0 1.57079 0</pose>
          <ray>
            <scan>
              <horizontal>
                <samples>1</samples>
                <resolution>1</resolution>
                <min_angle>0</min_angle>
                <max_angle>0</max_angle>
              </horizontal>
              <vertical>
                <samples>1</samples>
                <min_angle>0</min_angle>
                <max_angle>0</max_angle>
              </vertical>
            </scan>
            <range>
              <min>0.01</min>
              <max>0.04</max>
              <resolution>0.1</resolution>
            </range>
          </ray>
        </sensor>
        <sensor name='leftfront_cliff_sensor' type='ray'>
          <pose frame=''>0.15 0.04 0.027 0 1.57079 0</pose>
          <ray>
            <scan>
              <horizontal>
                <samples>1</samples>
                <resolution>1</resolution>
                <min_angle>0</min_angle>
                <max_angle>0</max_angle>
              </horizontal>
              <vertical>
                <samples>1</samples>
                <min_angle>0</min_angle>
                <max_angle>0</max_angle>
              </vertical>
            </scan>
            <range>
              <min>0.01</min>
              <max>0.04</max>
              <resolution>0.1</resolution>
            </range>
          </ray>
        </sensor>
        <sensor name='right_cliff_sensor' type='ray'>
          <pose frame=''>0.07 -0.14 0.027 0 1.57079 0</pose>
          <ray>
            <scan>
              <horizontal>
                <samples>1</samples>
                <resolution>1</resolution>
                <min_angle>0</min_angle>
                <max_angle>0</max_angle>
              </horizontal>
              <vertical>
                <samples>1</samples>
                <min_angle>0</min_angle>
                <max_angle>0</max_angle>
              </vertical>
            </scan>
            <range>
              <min>0.01</min>
              <max>0.04</max>
              <resolution>0.1</resolution>
            </range>
          </ray>
        </sensor>
        <sensor name='rightfront_cliff_sensor' type='ray'>
          <pose frame=''>0.15 -0.04 0.027 0 1.57079 0</pose>
          <ray>
            <scan>
              <horizontal>
                <samples>1</samples>
                <resolution>1</resolution>
                <min_angle>0</min_angle>
                <max_angle>0</max_angle>
              </horizontal>
              <vertical>
                <samples>1</samples>
                <min_angle>0</min_angle>
                <max_angle>0</max_angle>
              </vertical>
            </scan>
            <range>
              <min>0.01</min>
              <max>0.04</max>
              <resolution>0.1</resolution>
            </range>
          </ray>
        </sensor>
        <sensor name='wall_sensor' type='ray'>
          <pose frame=''>0.09 -0.12 0.059 0 0 -1</pose>
          <ray>
            <scan>
              <horizontal>
                <samples>1</samples>
                <resolution>1</resolution>
                <min_angle>0</min_angle>
                <max_angle>0</max_angle>
              </horizontal>
              <vertical>
                <samples>1</samples>
                <min_angle>0</min_angle>
                <max_angle>0</max_angle>
              </vertical>
            </scan>
            <range>
              <min>0.016</min>
              <max>0.04</max>
              <resolution>0.1</resolution>
            </range>
          </ray>
        </sensor>
        <pose frame=''>0 0 0 0 -0 0</pose>
        <self_collide>0</self_collide>
        <kinematic>0</kinematic>
      </link>
      <link name='create::left_wheel'>
        <pose frame=''>0 0.13 0.032 0 -0 0</pose>
        <inertial>
          <inertia>
            <ixx>0.001</ixx>
            <ixy>0</ixy>
            <ixz>0</ixz>
            <iyy>0.001</iyy>
            <iyz>0</iyz>
            <izz>0.001</izz>
          </inertia>
          <mass>0.01</mass>
        </inertial>
        <collision name='collision'>
          <pose frame=''>0 0 0 -0 1.5707 1.5707</pose>
          <geometry>
            <cylinder>
              <radius>0.033</radius>
              <length>0.023</length>
            </cylinder>
          </geometry>
          <surface>
            <friction>
              <ode>
                <mu>10</mu>
                <mu2>10</mu2>
                <fdir1>0 0 0</fdir1>
                <slip1>0</slip1>
                <slip2>0</slip2>
              </ode>
              <torsional>
                <ode/>
              </torsional>
            </friction>
            <contact>
              <ode/>
            </contact>
            <bounce/>
          </surface>
          <max_contacts>10</max_contacts>
        </collision>
        <visual name='visual'>
          <pose frame=''>0 0 0 -0 1.5707 1.5707</pose>
          <geometry>
            <cylinder>
              <radius>0.033</radius>
              <length>0.023</length>
            </cylinder>
          </geometry>
        </visual>
        <self_collide>0</self_collide>
        <kinematic>0</kinematic>
      </link>
      <link name='create::right_wheel'>
        <pose frame=''>0 -0.13 0.032 0 -0 0</pose>
        <inertial>
          <inertia>
            <ixx>0.001</ixx>
            <ixy>0</ixy>
            <ixz>0</ixz>
            <iyy>0.001</iyy>
            <iyz>0</iyz>
            <izz>0.001</izz>
          </inertia>
          <mass>0.01</mass>
        </inertial>
        <collision name='collision'>
          <pose frame=''>0 0 0 -0 1.5707 1.5707</pose>
          <geometry>
            <cylinder>
              <radius>0.033</radius>
              <length>0.023</length>
            </cylinder>
          </geometry>
          <surface>
            <friction>
              <ode>
                <mu>10</mu>
                <mu2>10</mu2>
                <fdir1>0 0 0</fdir1>
                <slip1>0</slip1>
                <slip2>0</slip2>
              </ode>
              <torsional>
                <ode/>
              </torsional>
            </friction>
            <contact>
              <ode/>
            </contact>
            <bounce/>
          </surface>
          <max_contacts>10</max_contacts>
        </collision>
        <visual name='visual'>
          <pose frame=''>0 0 0 -0 1.5707 1.5707</pose>
          <geometry>
            <cylinder>
              <radius>0.033</radius>
              <length>0.023</length>
            </cylinder>
          </geometry>
        </visual>
        <self_collide>0</self_collide>
        <kinematic>0</kinematic>
      </link>
      <joint name='create::left_wheel' type='revolute'>
        <parent>create::base</parent>
        <child>create::left_wheel</child>
        <axis>
          <xyz>0 1 0</xyz>
          <use_parent_model_frame>1</use_parent_model_frame>
          <limit>
            <lower>-1e+16</lower>
            <upper>1e+16</upper>
          </limit>
          <dynamics>
            <spring_reference>0</spring_reference>
            <spring_stiffness>0</spring_stiffness>
          </dynamics>
        </axis>
      </joint>
      <joint name='create::right_wheel' type='revolute'>
        <parent>create::base</parent>
        <child>create::right_wheel</child>
        <axis>
          <xyz>0 1 0</xyz>
          <use_parent_model_frame>1</use_parent_model_frame>
          <limit>
            <lower>-1e+16</lower>
            <upper>1e+16</upper>
          </limit>
          <dynamics>
            <spring_reference>0</spring_reference>
            <spring_stiffness>0</spring_stiffness>
          </dynamics>
        </axis>
      </joint>
      <link name='kinect::link'>
        <inertial>
          <mass>0.1</mass>
          <inertia>
            <ixx>1</ixx>
            <ixy>0</ixy>
            <ixz>0</ixz>
            <iyy>1</iyy>
            <iyz>0</iyz>
            <izz>1</izz>
          </inertia>
        </inertial>
        <collision name='collision'>
          <geometry>
            <box>
              <size>0.073 0.276 0.072</size>
            </box>
          </geometry>
          <max_contacts>10</max_contacts>
          <surface>
            <contact>
              <ode/>
            </contact>
            <bounce/>
            <friction>
              <torsional>
                <ode/>
              </torsional>
              <ode/>
            </friction>
          </surface>
        </collision>
        <visual name='visual'>
          <geometry>
            <mesh>
              <uri>model://kinect/meshes/kinect.dae</uri>
            </mesh>
          </geometry>
        </visual>
        <sensor name='camera' type='depth'>
          <update_rate>20</update_rate>
          <camera name='__default__'>
            <horizontal_fov>1.0472</horizontal_fov>
            <image>
              <width>640</width>
              <height>480</height>
              <format>R8G8B8</format>
            </image>
            <clip>
              <near>0.05</near>
              <far>3</far>
            </clip>
          </camera>
        </sensor>
        <pose frame=''>-0.087098 0 0.303857 0 -0 0</pose>
        <self_collide>0</self_collide>
        <kinematic>0</kinematic>
      </link>
      <joint name='create_rack' type='revolute'>
        <parent>create::base</parent>
        <child>rack</child>
        <axis>
          <xyz>0 0 1</xyz>
          <limit>
            <lower>0</lower>
            <upper>0</upper>
          </limit>
          <use_parent_model_frame>1</use_parent_model_frame>
          <dynamics>
            <spring_reference>0</spring_reference>
            <spring_stiffness>0</spring_stiffness>
          </dynamics>
        </axis>
      </joint>
      <joint name='kinect_rack' type='revolute'>
        <parent>kinect::link</parent>
        <child>rack</child>
        <axis>
          <xyz>0 0 1</xyz>
          <limit>
            <lower>0</lower>
            <upper>0</upper>
          </limit>
          <use_parent_model_frame>1</use_parent_model_frame>
          <dynamics>
            <spring_reference>0</spring_reference>
            <spring_stiffness>0</spring_stiffness>
          </dynamics>
        </axis>
      </joint>
      <pose frame=''>1.35712 -7.56594 0 0 -0 0</pose>
    </model>
  </world>
</sdf>
